output.txt
1001,12.30,100,0,buy, Filled,-1
1002,12.20,100,0,sell, Filled,-1
invalid oid
1004,12.15,300,300,buy, new,1
1005,12.15,100,100,buy, new,2
1004,12.15,600,600,buy, new,2
1005,12.15,100,100,buy, new,1
bid, 0, 12.15,700
ask, 0, 12.30,200
